Workbook

Sheet recipe form
G1: Fried Chicken
G2: Brathaehnchen
A4: intro: | Q4: vil / recipe code
Q7: quantity
A8: source: | Q8: calculator
Q9: 70
A11: ingredients: | J11: quantity | L11: unit | N11: 50 servings | O11: 75 servings | Q11: servings
A12: 1) | C12: Fryer Chicken, cut up | J12: 1.67 | L12: ct | N12: =IF(C12=0," ",(J12/$J$33)*50) -> 8.35 | O12: =IF(C12=0," ",(J12/$J$33)*75) -> 12.525 | Q12: =IF(C12=0," ",(J12/$J$33)*$Q$9) -> 11.69
A13: 2) | C13: Egg | J13: 3.33 | L13: ct | N13: =IF(C13=0," ",(J13/$J$33)*50) -> 16.65 | O13: =IF(C13=0," ",(J13/$J$33)*75) -> 24.975 | Q13: =IF(C13=0," ",(J13/$J$33)*$Q$9) -> 23.31
A14: 3) | C14: Butter | J14: 3.33 | L14: Tbsp | N14: =IF(C14=0," ",(J14/$J$33)*50) -> 16.65 | O14: =IF(C14=0," ",(J14/$J$33)*75) -> 24.975 | Q14: =IF(C14=0," ",(J14/$J$33)*$Q$9) -> 23.31
A15: 4) | C15: AP Flour | J15: 1.76 | L15: cup | N15: =IF(C15=0," ",(J15/$J$33)*50) -> 8.8 | O15: =IF(C15=0," ",(J15/$J$33)*75) -> 13.2 | Q15: =IF(C15=0," ",(J15/$J$33)*$Q$9) -> 12.32
A16: 5) | C16: Parsley | J16: 3.33 | L16: Tbsp | N16: =IF(C16=0," ",(J16/$J$33)*50) -> 16.65 | O16: =IF(C16=0," ",(J16/$J$33)*75) -> 24.975 | Q16: =IF(C16=0," ",(J16/$J$33)*$Q$9) -> 23.31
A17: 6) | C17: Salt | J17: 5 | L17: Tsp | N17: =IF(C17=0," ",(J17/$J$33)*50) -> 25 | O17: =IF(C17=0," ",(J17/$J$33)*75) -> 37.5 | Q17: =IF(C17=0," ",(J17/$J$33)*$Q$9) -> 35
A18: 7) | C18: Black Pepper | J18: 0.83 | L18: Tsp | N18: =IF(C18=0," ",(J18/$J$33)*50) -> 4.15 | O18: =IF(C18=0," ",(J18/$J$33)*75) -> 6.225 | Q18: =IF(C18=0," ",(J18/$J$33)*$Q$9) -> 5.81
A19: 8) | C19: Beer | J19: 0.83 | L19: cup | N19: =IF(C19=0," ",(J19/$J$33)*50) -> 4.15 | O19: =IF(C19=0," ",(J19/$J$33)*75) -> 6.225 | Q19: =IF(C19=0," ",(J19/$J$33)*$Q$9) -> 5.81
A20: 9) | C20: Vegetable Oil for Frying | N20: =IF(C20=0," ",(J20/$J$33)*50) -> 0 | O20: =IF(C20=0," ",(J20/$J$33)*75) -> 0 | Q20: =IF(C20=0," ",(J20/$J$33)*$Q$9) -> 0
A21: 10) | N21: =IF(C21=0," ",(J21/$J$33)*50) | O21: =IF(C21=0," ",(J21/$J$33)*75) | Q21: =IF(C21=0," ",(J21/$J$33)*$Q$9)
A22: 11) | N22: =IF(C22=0," ",(J22/$J$33)*50) | O22: =IF(C22=0," ",(J22/$J$33)*75) | Q22: =IF(C22=0," ",(J22/$J$33)*$Q$9)
A23: 12) | N23: =IF(C23=0," ",(J23/$J$33)*50) | O23: =IF(C23=0," ",(J23/$J$33)*75) | Q23: =IF(C23=0," ",(J23/$J$33)*$Q$9)
A24: 13) | N24: =IF(C24=0," ",(J24/$J$33)*50) | O24: =IF(C24=0," ",(J24/$J$33)*75) | Q24: =IF(C24=0," ",(J24/$J$33)*$Q$9)
A25: 14) | N25: =IF(C25=0," ",(J25/$J$33)*50) | O25: =IF(C25=0," ",(J25/$J$33)*75) | Q25: =IF(C25=0," ",(J25/$J$33)*$Q$9)
A26: 15) | N26: =IF(C26=0," ",(J26/$J$33)*50) | O26: =IF(C26=0," ",(J26/$J$33)*75) | Q26: =IF(C26=0," ",(J26/$J$33)*$Q$9)
A27: 16) | N27: =IF(C27=0," ",(J27/$J$33)*50) | O27: =IF(C27=0," ",(J27/$J$33)*75) | Q27: =IF(C27=0," ",(J27/$J$33)*$Q$9)
A28: 17) | N28: =IF(C28=0," ",(J28/$J$33)*50) | O28: =IF(C28=0," ",(J28/$J$33)*75) | Q28: =IF(C28=0," ",(J28/$J$33)*$Q$9)
A29: 18) | N29: =IF(C29=0," ",(J29/$J$33)*50) | O29: =IF(C29=0," ",(J29/$J$33)*75) | Q29: =IF(C29=0," ",(J29/$J$33)*$Q$9)
A30: 19) | N30: =IF(C30=0," ",(J30/$J$33)*50) | O30: =IF(C30=0," ",(J30/$J$33)*75) | Q30: =IF(C30=0," ",(J30/$J$33)*$Q$9)
A31: 20) | N31: =IF(C31=0," ",(J31/$J$33)*50) | O31: =IF(C31=0," ",(J31/$J$33)*75) | Q31: =IF(C31=0," ",(J31/$J$33)*$Q$9)
A33: As it appears above, recipe yields how many servings? | J33: 10
A36: cooking instructions:
A38: 1, Rub chicken with 2 tsp of the salt and 1/4 tsp of the pepper. Cover loosely with platisc wrap and refrigerate 1 hour. 2, Sift flour and remaining salt and pepper into a medium bowl. Beat in the eggs and beer until smooth. Add butter or maragarine and parsley; stir to combine. 3, Dip chicken, 1 piece at a time, in battter, turning chicken to caot heavily and evenly with batter. Let excess batter drip off. Place battered chicken on a backing sheet so they don't touch one another. Refrigertae, uncovered, 1 hour. 4, Preheat over to 350F. In a large saucepan or deep fryer, heat vetagable oil to 360F. Fry chciken until turns a light colour, about 10 mintues. Remove chicken; drain on paper towels. Arrange fried chicken in a shallow baking dish. Bake, uncovered, 20 to 30 mins or until crispy and browned.
L48: continued on additional instructions page…
A50: comments:
R54: =IF(Q1=0, " ", Q1)
R57: =IF(Q2=0, " ", Q2)
L60: continued on additional comments page…

Sheet additional instructions
A1: additional cooking instructions for | E1: =IF(('recipe form'!G1)=0," ",'recipe form'!G1) -> Fried Chicken | J1: =IF('recipe form'!Q1=0, " ",'recipe form'!Q1) | K1: =IF('recipe form'!Q2=0, " ",'recipe form'!Q2)
A4: =IF('recipe form'!A39=0, " ",'recipe form'!A39)
A5: =IF('recipe form'!A40=0, " ",'recipe form'!A40)
A6: =IF('recipe form'!A41=0, " ",'recipe form'!A41)
A7: =IF('recipe form'!A42=0, " ",'recipe form'!A42)
A8: =IF('recipe form'!A43=0, " ",'recipe form'!A43)
A9: =IF('recipe form'!A44=0, " ",'recipe form'!A44)
A10: =IF('recipe form'!A45=0, " ",'recipe form'!A45)
A11: =IF('recipe form'!A46=0, " ",'recipe form'!A46)
A12: =IF('recipe form'!A47=0, " ",'recipe form'!A47)
A13: =IF('recipe form'!A48:K48=0, " ",'recipe form'!A48:K48)
A15: please enter additional instructions below:

Sheet additional comments
A1: additional cooking comments for | E1: =IF(('recipe form'!G1)=0," ",'recipe form'!G1) -> Fried Chicken | J1: =IF('recipe form'!Q1=0, " ",'recipe form'!Q1) | K1: =IF('recipe form'!Q2=0, " ",'recipe form'!Q2)
A3: =IF('recipe form'!A52=0, " ",'recipe form'!A52)
A4: =IF('recipe form'!A53=0, " ",'recipe form'!A53)
A5: =IF('recipe form'!A54:Q54=0, " ",'recipe form'!A54:Q54)
A6: =IF('recipe form'!A55:Q55=0, " ",'recipe form'!A55:Q55)
A7: =IF('recipe form'!A56:Q56=0, " ",'recipe form'!A56:Q56)
A8: =IF('recipe form'!A57:Q57=0, " ",'recipe form'!A57:Q57)
A9: =IF('recipe form'!A58:Q58=0, " ",'recipe form'!A58:Q58)
A10: =IF('recipe form'!A59:Q59=0, " ",'recipe form'!A59:Q59)
A11: =IF('recipe form'!A60:K60=0, " ",'recipe form'!A60:K60)
A13: please enter additional comments below:

Sheet end recipe
G1: =IF('recipe form'!G1=0," ",'recipe form'!G1) -> Fried Chicken | Q1: =IF('recipe form'!Q1=0," ",'recipe form'!Q1)
G2: =IF('recipe form'!G2=0," ",'recipe form'!G2) -> Brathaehnchen | Q2: =IF('recipe form'!Q2=0," ",'recipe form'!Q2)
A4: intro: | E4: =IF('recipe form'!E4=0," ",'recipe form'!E4)
A5: =IF('recipe form'!A5=0," ",'recipe form'!A5)
A6: =IF('recipe form'!A6=0," ",'recipe form'!A6)
A8: source: | E8: =IF('recipe form'!E8=0," ",'recipe form'!E8)
A9: =IF('recipe form'!A9=0," ",'recipe form'!A9)
A11: ingredients: | J11: quantity | L11: unit | N11: from calculator, for | Q11: ='recipe form'!Q9 -> 70 | S11: people.
A13: 1) | C13: =IF('recipe form'!C12=0," ",'recipe form'!C12) -> Fryer Chicken, cut up | J13: =IF('recipe form'!J12=0," ",'recipe form'!J12) -> 1.67 | L13: =IF('recipe form'!L12=0," ",'recipe form'!L12) -> ct | O13: =IF('recipe form'!C12=0," ",('recipe form'!J12/'recipe form'!$J$33)*'recipe form'!$Q$9) -> 11.69 | Q13: =IF('recipe form'!L12=0," ",'recipe form'!L12) -> ct
A14: 2) | C14: =IF('recipe form'!C13=0," ",'recipe form'!C13) -> Egg | J14: =IF('recipe form'!J13=0," ",'recipe form'!J13) -> 3.33 | L14: =IF('recipe form'!L13=0," ",'recipe form'!L13) -> ct | O14: =IF('recipe form'!C13=0," ",('recipe form'!J13/'recipe form'!$J$33)*'recipe form'!$Q$9) -> 23.31 | Q14: =IF('recipe form'!L13=0," ",'recipe form'!L13) -> ct
A15: 3) | C15: =IF('recipe form'!C14=0," ",'recipe form'!C14) -> Butter | J15: =IF('recipe form'!J14=0," ",'recipe form'!J14) -> 3.33 | L15: =IF('recipe form'!L14=0," ",'recipe form'!L14) -> Tbsp | O15: =IF('recipe form'!J14=0," ",('recipe form'!J14/'recipe form'!$J$33)*'recipe form'!$Q$9) -> 23.31 | Q15: =IF('recipe form'!L14=0," ",'recipe form'!L14) -> Tbsp
A16: 4) | C16: =IF('recipe form'!C15=0," ",'recipe form'!C15) -> AP Flour | J16: =IF('recipe form'!J15=0," ",'recipe form'!J15) -> 1.76 | L16: =IF('recipe form'!L15=0," ",'recipe form'!L15) -> cup | O16: =IF('recipe form'!J15=0," ",('recipe form'!J15/'recipe form'!$J$33)*'recipe form'!$Q$9) -> 12.32 | Q16: =IF('recipe form'!L15=0," ",'recipe form'!L15) -> cup
A17: 5) | C17: =IF('recipe form'!C16=0," ",'recipe form'!C16) -> Parsley | J17: =IF('recipe form'!J16=0," ",'recipe form'!J16) -> 3.33 | L17: =IF('recipe form'!L16=0," ",'recipe form'!L16) -> Tbsp | O17: =IF('recipe form'!J16=0," ",('recipe form'!J16/'recipe form'!$J$33)*'recipe form'!$Q$9) -> 23.31 | Q17: =IF('recipe form'!L16=0," ",'recipe form'!L16) -> Tbsp
A18: 6) | C18: =IF('recipe form'!C17=0," ",'recipe form'!C17) -> Salt | J18: =IF('recipe form'!J17=0," ",'recipe form'!J17) -> 5 | L18: =IF('recipe form'!L17=0," ",'recipe form'!L17) -> Tsp | O18: =IF('recipe form'!J17=0," ",('recipe form'!J17/'recipe form'!$J$33)*'recipe form'!$Q$9) -> 35 | Q18: =IF('recipe form'!L17=0," ",'recipe form'!L17) -> Tsp
A19: 7) | C19: =IF('recipe form'!C18=0," ",'recipe form'!C18) -> Black Pepper | J19: =IF('recipe form'!J18=0," ",'recipe form'!J18) -> 0.83 | L19: =IF('recipe form'!L18=0," ",'recipe form'!L18) -> Tsp | O19: =IF('recipe form'!J18=0," ",('recipe form'!J18/'recipe form'!$J$33)*'recipe form'!$Q$9) -> 5.81 | Q19: =IF('recipe form'!L18=0," ",'recipe form'!L18) -> Tsp
A20: 8) | C20: =IF('recipe form'!C19=0," ",'recipe form'!C19) -> Beer | J20: =IF('recipe form'!J19=0," ",'recipe form'!J19) -> 0.83 | L20: =IF('recipe form'!L19=0," ",'recipe form'!L19) -> cup | O20: =IF('recipe form'!J19=0," ",('recipe form'!J19/'recipe form'!$J$33)*'recipe form'!$Q$9) -> 5.81 | Q20: =IF('recipe form'!L19=0," ",'recipe form'!L19) -> cup
A21: 9) | C21: =IF('recipe form'!C20=0," ",'recipe form'!C20) -> Vegetable Oil for Frying | J21: =IF('recipe form'!J20=0," ",'recipe form'!J20) | L21: =IF('recipe form'!L20=0," ",'recipe form'!L20) | O21: =IF('recipe form'!J20=0," ",('recipe form'!J20/'recipe form'!$J$33)*'recipe form'!$Q$9) | Q21: =IF('recipe form'!L20=0," ",'recipe form'!L20)
A22: 10) | C22: =IF('recipe form'!C21=0," ",'recipe form'!C21) | J22: =IF('recipe form'!J21=0," ",'recipe form'!J21) | L22: =IF('recipe form'!L21=0," ",'recipe form'!L21) | O22: =IF('recipe form'!J21=0," ",('recipe form'!J21/'recipe form'!$J$33)*'recipe form'!$Q$9) | Q22: =IF('recipe form'!L21=0," ",'recipe form'!L21)
A23: 11) | C23: =IF('recipe form'!C22=0," ",'recipe form'!C22) | J23: =IF('recipe form'!J22=0," ",'recipe form'!J22) | L23: =IF('recipe form'!L22=0," ",'recipe form'!L22) | O23: =IF('recipe form'!J22=0," ",('recipe form'!J22/'recipe form'!$J$33)*'recipe form'!$Q$9) | Q23: =IF('recipe form'!L22=0," ",'recipe form'!L22)
A24: 12) | C24: =IF('recipe form'!C23=0," ",'recipe form'!C23) | J24: =IF('recipe form'!J23=0," ",'recipe form'!J23) | L24: =IF('recipe form'!L23=0," ",'recipe form'!L23) | O24: =IF('recipe form'!J23=0," ",('recipe form'!J23/'recipe form'!$J$33)*'recipe form'!$Q$9) | Q24: =IF('recipe form'!L23=0," ",'recipe form'!L23)
A25: 13) | C25: =IF('recipe form'!C24=0," ",'recipe form'!C24) | J25: =IF('recipe form'!J24=0," ",'recipe form'!J24) | L25: =IF('recipe form'!L24=0," ",'recipe form'!L24) | O25: =IF('recipe form'!J24=0," ",('recipe form'!J24/'recipe form'!$J$33)*'recipe form'!$Q$9) | Q25: =IF('recipe form'!L24=0," ",'recipe form'!L24)
A26: 14) | C26: =IF('recipe form'!C25=0," ",'recipe form'!C25) | J26: =IF('recipe form'!J25=0," ",'recipe form'!J25) | L26: =IF('recipe form'!L25=0," ",'recipe form'!L25) | O26: =IF('recipe form'!J25=0," ",('recipe form'!J25/'recipe form'!$J$33)*'recipe form'!$Q$9) | Q26: =IF('recipe form'!L25=0," ",'recipe form'!L25)
... A32: 20) | C32: =IF('recipe form'!C31=0," ",'recipe form'!C31) | J32: =IF('recipe form'!J31=0," ",'recipe form'!J31) | L32: =IF('recipe form'!L31=0," ",'recipe form'!L31) | O32: =IF('recipe form'!J31=0," ",('recipe form'!J31/'recipe form'!$J$33)*'recipe form'!$Q$9) | Q32: =IF('recipe form'!L31=0," ",'recipe form'!L31)
I34: Recipe yield: | L34: =IF('recipe form'!J33=0," ",'recipe form'!J33) -> 10
A37: cooking instructions:
A38: =IF('recipe form'!A38=0," ",'recipe form'!A38) -> 1, Rub chicken with 2 tsp of the salt and 1/4 tsp of the pepper. Cover loosely with platisc wrap and refrigerate 1 hour. 2, Sift flour and remaining salt and pepper into a medium bowl. Beat in the eggs and beer until smooth. Add butter or maragarine and parsley; stir to combine. 3, Dip chicken, 1 piece at a time, in battter, turning chicken to caot heavily and evenly with batter. Let excess batter drip off. Place battered chicken on a backing sheet so they don't touch one another. Refrigertae, uncovered, 1 hour. 4, Preheat over to 350F. In a large saucepan or deep fryer, heat vetagable oil to 360F. Fry chciken until turns a light colour, about 10 mintues. Remove chicken; drain on paper towels. Arrange fried chicken in a shallow baking dish. Bake, uncovered, 20 to 30 mins or until crispy and browned.
A39: =IF('recipe form'!A39=0," ",'recipe form'!A39)
A40: =IF('recipe form'!A40=0," ",'recipe form'!A40)
A41: =IF('recipe form'!A41=0," ",'recipe form'!A41)
A42: =IF('recipe form'!A42=0," ",'recipe form'!A42)
A43: =IF('recipe form'!A43=0," ",'recipe form'!A43)
A44: =IF('recipe form'!A44=0," ",'recipe form'!A44)
A45: =IF('recipe form'!A45=0," ",'recipe form'!A45)
A46: =IF('recipe form'!A46=0," ",'recipe form'!A46)
A47: =IF('recipe form'!A48:K48=0," ",'recipe form'!A48:K48)
A48: =IF('additional instructions'!A17=0," ",'additional instructions'!A17)
A49: =IF('additional instructions'!A18=0," ",'additional instructions'!A18)
A50: =IF('additional instructions'!A19=0," ",'additional instructions'!A19)
A51: =IF('additional instructions'!A20=0," ",'additional instructions'!A20)
A52: =IF('additional instructions'!A21=0," ",'additional instructions'!A21)
...
